<?xml version="1.0" ?>
<!-- =================================================================================== -->
<!-- |    This document was autogenerated by xacro from src/kinova-ros/kinova_description/urdf/j2s6s200_standalone.xacro | -->
<!-- |    EDITING THIS FILE BY HAND IS NOT RECOMMENDED                                 | -->
<!-- =================================================================================== -->
<!-- j2s6_2 refers to jaco v2 6DOF spherical 2fingers -->
<robot name="j2s6s200">
     xmlns:xacro="http://www.ros.org/wiki/xacro">
    <material name="black">
        <color rgba="0.0 0.0 0.0 1.0"/>
    </material>
    <material name="blue">
        <color rgba="0.0 0.0 0.8 1.0"/>
    </material>
    <material name="green">
        <color rgba="0.0 0.8 0.0 1.0"/>
    </material>
    <material name="grey">
        <color rgba="0.2 0.2 0.2 1.0"/>
    </material>
    <material name="light_grey">
        <color rgba="0.4 0.4 0.4 1.0"/>
    </material>
    <material name="orange">
        <color rgba="1.0 0.423529411765 0.0392156862745 1.0"/>
    </material>
    <material name="brown">
        <color rgba="0.870588235294 0.811764705882 0.764705882353 1.0"/>
    </material>
    <material name="red">
        <color rgba="0.8 0.0 0.0 1.0"/>
    </material>
    <material name="white">
        <color rgba="1.0 1.0 1.0 1.0"/>
    </material>
    <!-- Material for the visual primitives -->
    <material name="anymal_material">
        <color rgba="0.7 0.7 0.7 1.0"/>
    </material>
  <!-- links      		mesh_no
   base           		0
   shoulder       		1
   arm            		2
   forearm        		3
   wrist          		4
   arm_mico       		5
   arm_half1 (7dof)		6
   arm_half2 (7dof)		7
   wrist_spherical_1  8
   wrist_spherical_2  9

   hand 3 finger  		55
   hand_2finger   		56
   finger_proximal		57
   finger_distal      58
-->  
    <link name="base">
      <inertial>
        <mass value="0.0"/>
        <origin rpy="0 0 0" xyz="0 0 0"/>
        <inertia ixx="0.0" ixy="0.0" ixz="0.0" iyy="0.0" iyz="0.0" izz="0.0"/>
      </inertial>
    </link>
  <link name="j2s6s200_link_base">
    <visual>
      <geometry>
        <mesh filename="/home/unknown/naomi_ws/src/kinova-ros/kinova_description/meshes/base.STL"/>
      </geometry>
      <material name="carbon_fiber">
         <color rgba="0.3 0.3 0.3 1"/>
      </material>
    </visual>
    <collision>
      <geometry>
        <mesh filename="/home/unknown/naomi_ws/src/kinova-ros/kinova_description/meshes/base.STL"/>
      </geometry>
    </collision>
    <inertial>
      <mass value="0.46784"/>
      <origin rpy="0 0 0" xyz="0 0 0.1255"/>
      <inertia ixx="0.000951270861568" ixy="0" ixz="0" iyy="0.000951270861568" iyz="0" izz="0.00037427200000000004"/>
    </inertial>
  </link>
   <joint name="j2s6s200_joint_base" type="fixed">
    <parent link="base"/>
    <child link="j2s6s200_link_base"/>
    <axis xyz="0 0 0"/>
    <origin rpy="0 0 0" xyz="0 0 0"/>
    <dynamics damping="0.0" friction="0.0"/>
  </joint> 
  <link name="j2s6s200_link_1">
    <visual>
      <geometry>
        <mesh filename="/home/unknown/naomi_ws/src/kinova-ros/kinova_description/meshes/shoulder.STL"/>
      </geometry>
      <material name="carbon_fiber">
         <color rgba="0.3 0.3 0.3 1"/>
      </material>
    </visual>
    <visual>
            <geometry>
                <mesh filename="/home/unknown/Documents/Posdoc/ModelsCads/urdf/kinova_description/meshes/ring_big.dae"/>
            </geometry>
        </visual>
    <collision>
      <geometry>
        <mesh filename="/home/unknown/naomi_ws/src/kinova-ros/kinova_description/meshes/shoulder.STL"/>
      </geometry>
    </collision>
    <inertial>
      <mass value="0.7477"/>
      <origin xyz="0 -0.002 -0.0605"/>
      <inertia ixx="0.0015203172520400004" ixy="0" ixz="0" iyy="0.0015203172520400004" iyz="0" izz="0.00059816"/>
    </inertial>
  </link>
  <joint name="j2s6s200_joint_1" type="revolute">
    <parent link="j2s6s200_link_base"/>
    <child link="j2s6s200_link_1"/>
    <axis xyz="0 0 1"/>
    <limit effort="40" lower="-6.28318530718" upper="6.28318530718"  velocity="0.6283185307179586"/>
    <origin rpy="0 3.141592653589793 0" xyz="0 0 0.15675"/>
    <dynamics damping="0.0" friction="0.0"/>
  </joint>
  <link name="j2s6s200_link_2">
    <visual>
      <geometry>
        <mesh filename="/home/unknown/naomi_ws/src/kinova-ros/kinova_description/meshes/arm.STL"/>
      </geometry>
      <material name="carbon_fiber">
         <color rgba="0.3 0.3 0.3 1"/>
      </material>
    </visual>
            <visual>
            <geometry>
                <mesh filename="/home/unknown/Documents/Posdoc/ModelsCads/urdf/kinova_description/meshes/ring_big.dae"/>
            </geometry>
        </visual>
    <collision>
      <geometry>
        <mesh filename="/home/unknown/naomi_ws/src/kinova-ros/kinova_description/meshes/arm.STL"/>
      </geometry>
    </collision>
    <inertial>
      <mass value="0.99"/>
      <origin xyz="0 -0.2065 -0.01"/>
      <inertia ixx="0.010502207990999999" ixy="0" ixz="0" iyy="0.0007920000000000001" iyz="0" izz="0.010502207990999999"/>
    </inertial>
  </link>
  <joint name="j2s6s200_joint_2" type="revolute">
    <parent link="j2s6s200_link_1"/>
    <child link="j2s6s200_link_2"/>
    <axis xyz="0 0 1"/>
    <limit effort="80" lower="0.8203047484373349" upper="5.462880558742252" velocity="0.6283185307179586"/>
    <origin rpy="-1.5707963267948966 0 3.141592653589793" xyz="0 0.0016 -0.11875"/>
    <dynamics damping="0.0" friction="0.0"/>
  </joint>
  <link name="j2s6s200_link_3">
    <visual>
      <geometry>
        <mesh filename="/home/unknown/naomi_ws/src/kinova-ros/kinova_description/meshes/forearm.STL"/>
      </geometry>
      <material name="carbon_fiber">
         <color rgba="0.3 0.3 0.3 1"/>
      </material>
    </visual>
            <visual>
            <geometry>
                <mesh filename="/home/unknown/Documents/Posdoc/ModelsCads/urdf/kinova_description/meshes/ring_big.dae"/>
            </geometry>
        </visual>
    <collision>
      <geometry>
        <mesh filename="/home/unknown/naomi_ws/src/kinova-ros/kinova_description/meshes/forearm.STL"/>
      </geometry>
    </collision>
    <inertial>
      <mass value="0.6763"/>
      <origin xyz="0 0.081 -0.0086"/>
      <inertia ixx="0.0014202243190800001" ixy="0" ixz="0" iyy="0.000304335" iyz="0" izz="0.0014202243190800001"/>
    </inertial>
  </link>
  <joint name="j2s6s200_joint_3" type="revolute">
    <parent link="j2s6s200_link_2"/>
    <child link="j2s6s200_link_3"/>
    <axis xyz="0 0 1"/>
    <limit effort="40" lower="0.33161255787892263" upper="5.951572749300664" velocity="0.6283185307179586"/>
    <origin rpy="0 3.141592653589793 0" xyz="0 -0.410 0"/>
    <dynamics damping="0.0" friction="0.0"/>
  </joint>
  <link name="j2s6s200_link_4">
    <visual>
      <geometry>
        <mesh filename="/home/unknown/naomi_ws/src/kinova-ros/kinova_description/meshes/wrist_spherical_1.STL"/>
      </geometry>
      <material name="carbon_fiber">
         <color rgba="0.3 0.3 0.3 1"/>
      </material>
    </visual>
            <visual>
            <geometry>
                <mesh filename="/home/unknown/Documents/Posdoc/ModelsCads/urdf/kinova_description/meshes/ring_small.dae"/>
            </geometry>
        </visual>
    <collision>
      <geometry>
        <mesh filename="/home/unknown/naomi_ws/src/kinova-ros/kinova_description/meshes/wrist_spherical_1.STL"/>
      </geometry>
    </collision>
    <inertial>
      <mass value="0.463"/>
      <origin xyz="0 0.0028848942 -0.0541932613"/>
      <inertia ixx="0.0004321316048000001" ixy="0" ixz="0" iyy="0.0004321316048000001" iyz="0" izz="9.260000000000001e-05"/>
    </inertial>
  </link>
  <joint name="j2s6s200_joint_4" type="revolute">
    <parent link="j2s6s200_link_3"/>
    <child link="j2s6s200_link_4"/>
    <axis xyz="0 0 1"/>
    <limit effort="20" lower="-6.28318530718" upper="6.28318530718" velocity="0.8377580409572781"/>
    <origin rpy="-1.5707963267948966 0 3.141592653589793" xyz="0 0.2073 -0.0114"/>
    <dynamics damping="0.0" friction="0.0"/>
  </joint>
  <link name="j2s6s200_link_5">
    <visual>
      <geometry>
        <mesh filename="/home/unknown/naomi_ws/src/kinova-ros/kinova_description/meshes/wrist_spherical_2.STL"/>
      </geometry>
      <material name="carbon_fiber">
        <color rgba="0.3 0.3 0.3 1"/>
      </material>
    </visual>
            <visual>
            <geometry>
                <mesh filename="/home/unknown/Documents/Posdoc/ModelsCads/urdf/kinova_description/meshes/ring_small.dae"/>
            </geometry>
        </visual>
    <collision>
      <geometry>
        <mesh filename="/home/unknown/naomi_ws/src/kinova-ros/kinova_description/meshes/wrist_spherical_2.STL"/>
      </geometry>
    </collision>
    <inertial>
      <mass value="0.463"/>
      <origin xyz="0 0.0497208855 -0.0028562765"/>
      <inertia ixx="0.0004321316048000001" ixy="0" ixz="0" iyy="9.260000000000001e-05" iyz="0" izz="0.0004321316048000001"/>
    </inertial>
  </link>
  <joint name="j2s6s200_joint_5" type="revolute">
    <parent link="j2s6s200_link_4"/>
    <child link="j2s6s200_link_5"/>
    <axis xyz="0 0 1"/>
    <limit effort="20" lower="0.5235987755982988" upper="5.759586531581287" velocity="0.8377580409572781"/>
    <origin rpy="1.5707963267948966 0 3.141592653589793" xyz="0 0 -0.10375"/>
    <dynamics damping="0.0" friction="0.0"/>
  </joint>
  <link name="j2s6s200_link_6">
    <visual>
      <geometry>
        <mesh filename="/home/unknown/naomi_ws/src/kinova-ros/kinova_description/meshes/hand_2finger.STL"/>
      </geometry>
      <material name="carbon_fiber">
         <color rgba="0.3 0.3 0.3 1"/>
      </material>
    </visual>
            <visual>
            <geometry>
                <mesh filename="/home/unknown/Documents/Posdoc/ModelsCads/urdf/kinova_description/meshes/ring_small.dae"/>
            </geometry>
        </visual>
    <collision>
      <geometry>
        <mesh filename="/home/unknown/naomi_ws/src/kinova-ros/kinova_description/meshes/hand_2finger.STL"/>
      </geometry>
    </collision>
    <inertial>
      <mass value="0.99"/>
      <origin xyz="0 0 -0.06"/>
      <inertia ixx="0.00034532361869999995" ixy="0" ixz="0" iyy="0.00034532361869999995" iyz="0" izz="0.0005815999999999999"/>
    </inertial>
  </link>
  <joint name="j2s6s200_joint_6" type="revolute">
    <parent link="j2s6s200_link_5"/>
    <child link="j2s6s200_link_6"/>
    <axis xyz="0 0 1"/>
    <limit effort="20" velocity="0.8377580409572781"/>
    <origin rpy="-1.5707963267948966 0 3.141592653589793" xyz="0 0.10375 0"/>
    <dynamics damping="0.0" friction="0.0"/>
  </joint>
  <link name="j2s6s200_end_effector">
    <inertial>
      <mass value="0"/>
      <origin xyz="0 0 0"/>
      <inertia ixx="0.00034532361869999995" ixy="0" ixz="0" iyy="0.00034532361869999995" iyz="0" izz="0.0005815999999999999"/>
    </inertial>
  </link>
  <joint name="j2s6s200_joint_end_effector" type="fixed">
    <parent link="j2s6s200_link_6"/>
    <child link="j2s6s200_end_effector"/>
    <axis xyz="0 0 0"/>
    <origin rpy="3.141592653589793 0 1.5707963267948966" xyz="0 0 -0.1600"/>
  </joint>
</robot>
